<?xml version="1.0" ?>
<!-- generated from models/kobuki_model/model.sdf -->
<robot name="kobuki_model">
  <joint name="gyro_joint" type="fixed">
    <parent link="base_link"/>
    <child link="imu_link"/>
    <origin xyz="0.056  0.062  0.0102" rpy="0 0 0"/>
    <axis xyz="0 1 0"/>
    <limit lower="0" upper="0" effort="0" velocity="0"/>
  </joint>
  <joint name="base_joint" type="fixed">
    <parent link="base_footprint"/>
    <child link="base_link"/>
    <origin xyz="0   0   0.01" rpy="0 0 0"/>
    <axis xyz="0 0 0"/>
    <limit lower="0" upper="0" effort="0" velocity="0"/>
  </joint>
  <joint name="laser_joint" type="fixed">
    <parent link="base_link"/>
    <child link="laser"/>
    <origin xyz="0.115 0    0.12" rpy="0 0 0"/>
    <axis xyz="0 0 1"/>
    <limit lower="0" upper="0" effort="0" velocity="0"/>
  </joint>
  <joint name="wheel_left_joint" type="revolute">
    <parent link="base_footprint"/>
    <child link="wheel_left_link"/>
    <origin xyz="0     0.115  0.0352" rpy="-1.5708  0      0"/>
    <axis xyz="0 0 1"/>
    <limit lower="-1e+16" upper="1e+16" effort="0.0" velocity="0.0"/>
  </joint>
  <joint name="wheel_right_joint" type="revolute">
    <parent link="base_footprint"/>
    <child link="wheel_right_link"/>
    <origin xyz="0     -0.115   0.0352" rpy="-1.5708  0      0"/>
    <axis xyz="0 0 1"/>
    <limit lower="-1e+16" upper="1e+16" effort="0.0" velocity="0.0"/>
  </joint>
  <link name="base_footprint">
    <inertial>
      <mass value="2.4213"/>
      <origin xyz="9.860e-03 2.000e-05 1.027e-02" rpy="0 0 0"/>
      <inertia ixx="0.0224044" ixy="-2.89213e-06" ixz="4.10737e-06" iyy="0.0226237" iyz="-1.24762e-06" izz="0.0394834"/>
    </inertial>
    <collision name="base_footprint_fixed_joint_lump__base_collision">
      <origin xyz="0      0      0.06969" rpy="0 0 0"/>
      <geometry>
        <cylinder radius="0.178" length="0.10938"/>
      </geometry>
    </collision>
    <collision name="base_footprint_fixed_joint_lump__caster_back_link_collision_1">
      <origin xyz="-0.135    0       0.01919" rpy="-1.5708  0      0"/>
      <geometry>
        <cylinder radius="0.017" length="0.0176"/>
      </geometry>
    </collision>
    <collision name="base_footprint_fixed_joint_lump__caster_front_link_collision_2">
      <origin xyz="0.115  0     0.0172" rpy="-1.5708  0      0"/>
      <geometry>
        <cylinder radius="0.017" length="0.0176"/>
      </geometry>
    </collision>
    <visual name="base_footprint_fixed_joint_lump__base_link_visual">
      <origin xyz="0.001   0      0.06219" rpy="0 0 0"/>
      <geometry>
        <mesh filename="package://tbot_sim/models/kobuki_model/meshes/main_body.dae OR tbot_sim/models/kobuki/meshes/main_body.dae" scale="1 1 1"/>
      </geometry>
    </visual>
  </link>
  <link name="imu_link">
    <inertial>
      <mass value="0"/>
      <origin xyz="0 0 0" rpy="0 0 0"/>
      <inertia ixx="0" ixy="0" ixz="0" iyy="0" iyz="0" izz="0"/>
    </inertial>
  </link>
  <link name="base_link">
    <inertial>
      <mass value="2.4"/>
      <origin xyz="0.01 0   0" rpy="0 0 0"/>
      <inertia ixx="0.019995" ixy="0.000" ixz="0.000" iyy="0.019995" iyz="0.000" izz="0.03675"/>
    </inertial>
  </link>
  <link name="laser">
    <inertial>
      <mass value="0.1"/>
      <origin xyz="0 0 0" rpy="0 0 0"/>
      <inertia ixx="0" ixy="0" ixz="0" iyy="0" iyz="0" izz="0"/>
    </inertial>
    <collision name="collision-laser">
      <origin xyz="0     0    -0.001" rpy="0 0 0"/>
      <geometry>
        <box size="0.055 0.055 0.075"/>
      </geometry>
    </collision>
    <visual name="visual">
      <origin xyz="0 0 0" rpy="0 0 0"/>
      <geometry>
        <mesh filename="package://tbot_sim/models/hokuyo/meshes/hokuyo.dae OR tbot_sim/models/kobuki_model/meshes/hokuyo.dae" scale="1.0 1.0 1.0"/>
      </geometry>
    </visual>
  </link>
  <link name="wheel_left_link">
    <inertial>
      <mass value="0.01"/>
      <origin xyz="0 0 0" rpy="0 0 0"/>
      <inertia ixx="0.001" ixy="0" ixz="0" iyy="0.001" iyz="0" izz="0.001"/>
    </inertial>
    <collision name="wheel_left_link_collision">
      <origin xyz="0 0 0" rpy="0 0 0"/>
      <geometry>
        <cylinder radius="0.0352" length="0.0206"/>
      </geometry>
    </collision>
    <visual name="wheel_left_link_visual">
      <origin xyz="0 0 0" rpy="0 0 0"/>
      <geometry>
        <mesh filename="package://tbot_sim/models/kobuki_model/meshes/wheel.dae OR tbot_sim/models/kobuki/meshes/wheel.dae" scale="1 1 1"/>
      </geometry>
    </visual>
  </link>
  <link name="wheel_right_link">
    <inertial>
      <mass value="0.01"/>
      <origin xyz="0 0 0" rpy="0 0 0"/>
      <inertia ixx="0.001" ixy="0" ixz="0" iyy="0.001" iyz="0" izz="0.001"/>
    </inertial>
    <collision name="wheel_right_link_collision">
      <origin xyz="0 0 0" rpy="0 0 0"/>
      <geometry>
        <cylinder radius="0.035" length="0.0206"/>
      </geometry>
    </collision>
    <visual name="wheel_right_link_visual">
      <origin xyz="0 0 0" rpy="0 0 0"/>
      <geometry>
        <mesh filename="package://tbot_sim/models/kobuki_model/meshes/wheel.dae OR tbot_sim/models/kobuki/meshes/wheel.dae" scale="1 1 1"/>
      </geometry>
    </visual>
  </link>
</robot>
